<sdf version="1.7">
  <model name="issac_seven">

   
    <link name="base_link">
      <inertial>
        <pose>-0.024847979688122499 -0.0112943222529918 0.036263878636560297 0 0 0</pose>
        <mass>16.045770899709201</mass>
        <inertia>
          <ixx>0.14021509634615001</ixx>
          <ixy>0.00053572133634947699</ixy>
          <ixz>-0.00080546217759708901</ixz>
          <iyy>0.19965922959145199</iyy>
          <iyz>9.8445879167150305e-05</iyz>
          <izz>0.31923817163479101</izz>
        </inertia>
      </inertial>
      <collision name="base_link_collision">
        <pose>0 0 0 0.06 0 0</pose>
        <geometry>
          <box>
           <size>0.5 0.4 0.12</size>
          </box>
        </geometry>
      </collision>
      <visual name="base_link_visual">
        <pose>0 0 0 0 0 0</pose>
        <geometry>
          <mesh>
            <scale>1 1 1</scale>
            <uri>package://bugger/meshes/visual/base_link.STL</uri>
          </mesh>
        </geometry>
        <material>
          <diffuse>0.990196109 1 1 1</diffuse>
          <ambient>0.990196109 1 1 1</ambient>
        </material>
      </visual>
    </link>


    <joint name="dcamera" type="fixed">
      <pose relative_to="base_link">0 0 0 0 0 0</pose>
      <parent>base_link</parent>
      <child>depth_camera</child>
      <axis>
        <xyz>0 0 1</xyz>
        <limit>
          <lower>-1e+16</lower>
          <upper>1e+16</upper>
        </limit>
        <dynamics>
          <spring_reference>0</spring_reference>
          <spring_stiffness>0</spring_stiffness>
        </dynamics>
      </axis>
    </joint>
    <link name="depth_camera">
      <pose relative_to="dcamera">0 0 0 0 0 0</pose>
      <inertial>
        <pose>0.23648247450318899 0.00043943367118937099 0.0243999681342368 0 0 0</pose>
        <mass>0.110215155258526</mass>
        <inertia>
          <ixx>0.00013522664389295199</ixx>
          <ixy>-6.0551668132357804e-09</ixy>
          <ixz>-1.16922717897847e-08</ixz>
          <iyy>1.2640405785326901e-05</iyy>
          <iyz>-4.4302143023925e-12</iyz>
          <izz>0.00013333399219561201</izz>
        </inertia>
      </inertial>
      <collision name="depth_camera_collision">
        <pose>0 0 0 0 0 0</pose>
        <geometry>
          <box>
           <size>0.06 0.06 0.04</size>
          </box>
        </geometry>
      </collision>
      <visual name="depth_camera_visual">
        <pose>0 0 0 0 0 0</pose>
        <geometry>
          <mesh>
            <scale>1 1 1</scale>
            <uri>package://bugger/meshes/visual/depth_camera.STL</uri>
          </mesh>
        </geometry>
        <material>
          <diffuse>0.622548997 0.622548997 0.622548997 1</diffuse>
          <ambient>0.622548997 0.622548997 0.622548997 1</ambient>
        </material>
      </visual>
      <sensor name="depth_camera" type="rgbd_camera">
        <always_on>true</always_on>
        <visualize>true</visualize>
        <update_rate>15</update_rate>
        <topic>camera</topic>
        <gz_frame_id>depth_camera</gz_frame_id>
        <camera name="depth_camera">
          <horizontal_fov>1.5708</horizontal_fov>
          <image>
            <width>1366</width>
            <height>768</height>
            <format>R8G8B8</format>
          </image>
          <clip>
            <near>1.0</near>
            <far>10.0</far>
          </clip>
          <noise>
            <type>gaussian</type>
            <mean>0.0</mean>
            <stddev>0.007</stddev>
          </noise>
        </camera>
      </sensor>
    </link>

    <joint name="frontcastor" type="revolute">
      <pose relative_to="base_link">0.18875 -0.01515 -0.017100000000000001 0 0 0.029377</pose>
      <parent>base_link</parent>
      <child>front_castor</child>
      <axis>
        <xyz>0 0 -1</xyz>
        <limit>
          <lower>-1e+16</lower>
          <upper>1e+16</upper>
        </limit>
        <dynamics>
          <damping>0.001</damping>
          <friction>0.0</friction>
          <spring_reference>0</spring_reference>
          <spring_stiffness>0</spring_stiffness>
        </dynamics>
      </axis>
    </joint>
    <link name="front_castor">
      <pose relative_to="frontcastor">0 0 0 0 0 0</pose>
      <inertial>
        <pose>-1.4723097191415799e-06 -1.31477673193103e-09 -0.0075492724826718999 0 0 0</pose>
        <mass>0.188433066543013</mass>
        <inertia>
          <ixx>0.00032536537878349398</ixx>
          <ixy>-1.03442588377839e-06</ixy>
          <ixz>-7.8020030948336006e-09</ixz>
          <iyy>0.00019979281882914</iyy>
          <iyz>1.2483225335555199e-18</iyz>
          <izz>0.00046852584631811798</izz>
        </inertia>
      </inertial>
      <collision name="front_castor_collision">
        <pose>0 0 0 0 0 0</pose>
        <geometry>
          <sphere>
            <radius>0.03</radius>
          </sphere>
        </geometry>
        <surface>
          <friction>
            <ode>
              <mu>0.0</mu>
              <mu2>0.0</mu2>
            </ode>
          </friction>
        </surface>
      </collision>
      <visual name="front_castor_visual">
        <pose>0 0 0 0 0 0</pose>
        <geometry>
          <mesh>
            <scale>1 1 1</scale>
            <uri>package://bugger/meshes/visual/front_castor.STL</uri>
          </mesh>
        </geometry>
        <material>
          <diffuse>0.210784316 0.5 0.774509847 1</diffuse>
          <ambient>0.210784316 0.5 0.774509847 1</ambient>
        </material>
      </visual>
    </link>


    <joint name="ffcastor" type="revolute">
      <pose relative_to="front_castor">0.050369999999999998 0 -0.044173999999999998 0 0 0</pose>
      <parent>front_castor</parent>
      <child>ff_castor</child>
      <axis>
        <xyz>0 1 0</xyz>
        <limit>
          <lower>-1e+16</lower>
          <upper>1e+16</upper>
        </limit>
        <dynamics>
          <damping>0.001</damping>
          <friction>0.0001</friction>
          <spring_reference>0</spring_reference>
          <spring_stiffness>0</spring_stiffness>
        </dynamics>
      </axis>
    </joint>
    <link name="ff_castor">
      <pose relative_to="ffcastor">0 0 0 0 0 0</pose>
      <inertial>
        <pose>-2.0192463993318199e-05 -0.000750000002212592 -0.00332627702110022 0 0 0</pose>
        <mass>0.175593255248327</mass>
        <inertia>
          <ixx>5.2232830345647699e-05</ixx>
          <ixy>1.0270274485458401e-20</ixy>
          <ixz>1.34069473916505e-21</ixz>
          <iyy>8.6772528526853402e-05</iyy>
          <iyz>1.5632392087294701e-21</iyz>
          <izz>5.2232830345647699e-05</izz>
        </inertia>
      </inertial>
      <collision name="ff_castor_collision">
        <pose>0 0 0 0 0 0</pose>
        <geometry>
          <sphere>
            <radius>0.025</radius>
          </sphere>
        </geometry>
        <surface>
          <friction>
            <ode>
              <mu>0.0</mu>
              <mu2>0.0</mu2>
            </ode>
          </friction>
        </surface>
      </collision>
      <visual name="ff_castor_visual">
        <pose>0 0 0 0 0 0</pose>
        <geometry>
          <mesh>
            <scale>1 1 1</scale>
            <uri>package://bugger/meshes/visual/ff_castor.STL</uri>
          </mesh>
        </geometry>
        <material>
          <diffuse>0.117647059 0.117647059 0.117647059 1</diffuse>
          <ambient>0.117647059 0.117647059 0.117647059 1</ambient>
        </material>
      </visual>
    </link>

    
    <joint name="frcastor" type="revolute">
      <pose relative_to="front_castor">-0.047156000000000003 0 -0.04657 0 0 0</pose>
      <parent>front_castor</parent>
      <child>fr_castor</child>
      <axis>
        <xyz>0 1 0</xyz>
        <limit>
          <lower>-1e+16</lower>
          <upper>1e+16</upper>
        </limit>
        <dynamics>
          <damping>0.001</damping>
          <friction>0.0001</friction>
          <spring_reference>0</spring_reference>
          <spring_stiffness>0</spring_stiffness>
        </dynamics>
      </axis>
    </joint>
    <link name="fr_castor">
      <pose relative_to="frcastor">0 0 0 0 0 0</pose>
      <inertial>
        <pose>-0.0031935641557507802 -0.00071666666666692102 -0.00093041632610346703 0 0 0</pose>
        <mass>0.175593255248328</mass>
        <inertia>
          <ixx>5.2232830345647699e-05</ixx>
          <ixy>3.3881317890171999e-21</ixy>
          <ixz>-2.97557288424969e-22</ixz>
          <iyy>8.6772528526853402e-05</iyy>
          <iyz>5.6456260053518302e-21</iyz>
          <izz>5.2232830345647699e-05</izz>
        </inertia>
      </inertial>
      <collision name="fr_castor_collision">
        <pose>0 0 0 0 0 0</pose>
        <geometry>
          <sphere>
            <radius>0.025</radius>
          </sphere>
        </geometry>
        <surface>
          <friction>
            <ode>
              <mu>0.0</mu>
              <mu2>0.0</mu2>
            </ode>
          </friction>
        </surface>
      </collision>
      <visual name="fr_castor_visual">
        <pose>0 0 0 0 0 0</pose>
        <geometry>
          <mesh>
            <scale>1 1 1</scale>
            <uri>package://bugger/meshes/visual/fr_castor.STL</uri>
          </mesh>
        </geometry>
        <material>
          <diffuse>0.117647059 0.117647059 0.117647059 1</diffuse>
          <ambient>0.117647059 0.117647059 0.117647059 1</ambient>
        </material>
      </visual>
    </link>

    
    <joint name="frontlidar" type="fixed">
      <pose relative_to="base_link">0 0 0 0 0 0</pose>
      <parent>base_link</parent>
      <child>front_lidar</child>
      <axis>
        <xyz>0 0 1</xyz>
        <limit>
          <lower>-1e+16</lower>
          <upper>1e+16</upper>
        </limit>
        <dynamics>
          <spring_reference>0</spring_reference>
          <spring_stiffness>0</spring_stiffness>
        </dynamics>
      </axis>
    </joint>
    <link name="front_lidar">
      <pose relative_to="frontlidar">0 0 0 0 0 0</pose>
      <inertial>
        <pose>0.19891014088599099 0.00123094971141513 0.198753746521451 0 0 0</pose>
        <mass>0.064328080040047697</mass>
        <inertia>
          <ixx>1.20633668132692e-05</ixx>
          <ixy>1.77128240148071e-08</ixy>
          <ixz>-2.2712293543601499e-06</ixz>
          <iyy>2.8634339781218001e-05</iyy>
          <iyz>7.5586989060525997e-09</iyz>
          <izz>3.7413990749141902e-05</izz>
        </inertia>
      </inertial>
      <collision name="front_lidar_collision">
        <pose>0 0 0 0 0 0</pose>
        <geometry>
          <cylinder>
            <radius>0.03</radius>
            <length>0.04</length>
          </cylinder>
        </geometry>
      </collision>
      <visual name="front_lidar_visual">
        <pose>0 0 0 0 0 0</pose>
        <geometry>
          <mesh>
            <scale>1 1 1</scale>
            <uri>package://bugger/meshes/visual/front_lidar.STL</uri>
          </mesh>
        </geometry>
        <material>
          <diffuse>0.990196109 1 1 1</diffuse>
          <ambient>0.990196109 1 1 1</ambient>
        </material>
      </visual>
      <sensor name='lidar' type='gpu_lidar'>
        <topic>scan</topic>
        <update_rate>10</update_rate>
        <lidar>
          <scan>
            <horizontal>
              <samples>180</samples>
              <resolution>1.000</resolution>
              <min_angle>-1.5708</min_angle>
              <max_angle>1.5708</max_angle>
            </horizontal>
          </scan>
          <range>
            <min>0.35</min>
            <max>12.0</max>
            <resolution>0.02</resolution>
          </range>
          <noise>
            <type>gaussian</type>
            <mean>0.0</mean>
            <stddev>0.01</stddev>
          </noise>
        </lidar>
        <alwaysOn>1</alwaysOn>
        <visualize>true</visualize>
      </sensor>
    </link>

   
    <joint name="leftwheel" type="revolute">
      <pose relative_to="base_link">-0.0022133999999999999 0.19925000000000001 -0.035000000000000003 0 0 0</pose>
      <parent>base_link</parent>
      <child>left_wheel</child>
      <axis>
        <xyz>0 1 0</xyz>
        <limit>
          <lower>-1e+16</lower>
          <upper>1e+16</upper>
        </limit>
        <dynamics>
          <damping>0.1</damping>
          <friction>0.1</friction>
          <spring_reference>0</spring_reference>
          <spring_stiffness>0</spring_stiffness>
        </dynamics>
      </axis>
    </joint>
    <link name="left_wheel">
      <pose relative_to="leftwheel">0 0 0 0 0 0</pose>
      <inertial>
        <pose>-1.45521954928451e-05 0.00068810812810338195 1.7090687301046799e-05 0 0 0</pose>
        <mass>0.266150143776577</mass>
        <inertia>
          <ixx>0.00036335504528209502</ixx>
          <ixy>4.8306260702547e-08</ixy>
          <ixz>-6.2219104212407795e-08</ixz>
          <iyy>0.00065937229319055796</iyy>
          <iyz>-5.6201212546706798e-08</iyz>
          <izz>0.00036391099080892601</izz>
        </inertia>
      </inertial>
      <collision name="left_wheel_collision">
        <pose>0 0 0 1.5707 0 0</pose>
        <geometry>
          <cylinder>
            <radius>0.06</radius>
            <length>0.04</length>
          </cylinder>
        </geometry>
        <surface>
          <friction>
            <ode>
              <mu>1.0</mu>
              <mu2>1.0</mu2>
              <fdir1>0 0 0</fdir1>
              <slip1>0.0</slip1>
              <slip2>0.0</slip2>
            </ode>
          </friction>
          <contact>
            <ode>
              <min_depth>0.001</min_depth>
              <kp>1e6</kp>
              <kd>100</kd>
            </ode>
          </contact>
        </surface>
      </collision>
      <visual name="left_wheel_visual">
        <pose>0 0 0 0 0 0</pose>
        <geometry>
          <mesh>
            <scale>1 1 1</scale>
            <uri>package://bugger/meshes/visual/left_wheel.STL</uri>
          </mesh>
        </geometry>
        <material>
          <diffuse>1 1 1 1</diffuse>
          <ambient>1 1 1 1</ambient>
        </material>
      </visual>
    </link>

    
    <joint name="rearcastor" type="revolute">
      <pose relative_to="base_link">-0.18917999999999999 0.01515 -0.017100000000000001 0 0 -0.05507699999999998</pose>
      <parent>base_link</parent>
      <child>rear_castor</child>
      <axis>
        <xyz>0 0 -1</xyz>
        <limit>
          <lower>-1e+16</lower>
          <upper>1e+16</upper>
        </limit>
        <dynamics>
          <damping>0.001</damping>
          <friction>0.0</friction>
          <spring_reference>0</spring_reference>
          <spring_stiffness>0</spring_stiffness>
        </dynamics>
      </axis>
    </joint>
    <link name="rear_castor">
      <pose relative_to="rearcastor">0 0 0 0 0 0</pose>
      <inertial>
        <pose>-1.49030058516075e-06 -1.26075393458436e-08 -0.0075492724826721203 0 0 0</pose>
        <mass>0.188433066543014</mass>
        <inertia>
          <ixx>0.00032528900744475503</ixx>
          <ixy>1.93657213819524e-06</ixy>
          <ixz>-7.8020030951416708e-09</ixz>
          <iyy>0.00019986919016788099</iyy>
          <iyz>1.2453551182800499e-18</iyz>
          <izz>0.00046852584631811999</izz>
        </inertia>
      </inertial>
      <collision name="rear_castor_collision">
        <pose>0 0 0 0 0 0</pose>
        <geometry>
          <sphere>
            <radius>0.03</radius>
          </sphere>
        </geometry>
        <surface>
          <friction>
            <ode>
              <mu>0.0</mu>
              <mu2>0.0</mu2>
            </ode>
          </friction>
        </surface>
      </collision>
      <visual name="rear_castor_visual">
        <pose>0 0 0 0 0 0</pose>
        <geometry>
          <mesh>
            <scale>1 1 1</scale>
            <uri>package://bugger/meshes/visual/rear_castor.STL</uri>
          </mesh>
        </geometry>
        <material>
          <diffuse>0.210784316 0.5 0.774509847 1</diffuse>
          <ambient>0.210784316 0.5 0.774509847 1</ambient>
        </material>
      </visual>
    </link>

   
    <joint name="rfcastor" type="revolute">
      <pose relative_to="rear_castor">0.05033 0 -0.050826000000000003 0 0 0</pose>
      <parent>rear_castor</parent>
      <child>rf_castor</child>
      <axis>
        <xyz>0 1 0</xyz>
        <limit>
          <lower>-1e+16</lower>
          <upper>1e+16</upper>
        </limit>
        <dynamics>
          <damping>0.001</damping>
          <friction>0.0001</friction>
          <spring_reference>0</spring_reference>
          <spring_stiffness>0</spring_stiffness>
        </dynamics>
      </axis>
    </joint>
    <link name="rf_castor">
      <pose relative_to="rfcastor">0 0 0 0 0 0</pose>
      <inertial>
        <pose>2.0192464001977902e-05 -0.00074999999999414402 0.0033262770211004399 0 0 0</pose>
        <mass>0.175593255248329</mass>
        <inertia>
          <ixx>5.2232830345648201e-05</ixx>
          <ixy>-1.8422966602780999e-20</ixy>
          <ixz>1.2901995018405e-21</ixz>
          <iyy>8.6772528526854107e-05</iyy>
          <iyz>5.0656445455467203e-21</iyz>
          <izz>5.2232830345648201e-05</izz>
        </inertia>
      </inertial>
      <collision name="rf_castor_collision">
        <pose>0 0 0 0 0 0</pose>
        <geometry>
          <sphere>
            <radius>0.025</radius>
          </sphere>
        </geometry>
        <surface>
          <friction>
            <ode>
              <mu>0.0</mu>
              <mu2>0.0</mu2>
            </ode>
          </friction>
        </surface>
      </collision>
      <visual name="rf_castor_visual">
        <pose>0 0 0 0 0 0</pose>
        <geometry>
          <mesh>
            <scale>1 1 1</scale>
            <uri>package://bugger/meshes/visual/rf_castor.STL</uri>
          </mesh>
        </geometry>
        <material>
          <diffuse>0.117647059 0.117647059 0.117647059 1</diffuse>
          <ambient>0.117647059 0.117647059 0.117647059 1</ambient>
        </material>
      </visual>
    </link>

    
    <joint name="rrcastor" type="revolute">
      <pose relative_to="rear_castor">-0.047156000000000003 0 -0.04657 0 0 0</pose>
      <parent>rear_castor</parent>
      <child>rr_castor</child>
      <axis>
        <xyz>0 1 0</xyz>
        <limit>
          <lower>-1e+16</lower>
          <upper>1e+16</upper>
        </limit>
        <dynamics>
          <damping>0.001</damping>
          <friction>0.0001</friction>
          <spring_reference>0</spring_reference>
          <spring_stiffness>0</spring_stiffness>
        </dynamics>
      </axis>
    </joint>
    <link name="rr_castor">
      <pose relative_to="rrcastor">0 0 0 0 0 0</pose>
      <inertial>
        <pose>-0.0031935641557378999 -0.00071666666666214695 -0.00093041632610379999 0 0 0</pose>
        <mass>0.175593255248329</mass>
        <inertia>
          <ixx>5.2232830345648099e-05</ixx>
          <ixy>-9.5291206566108803e-21</ixy>
          <ixz>-2.70252236776506e-21</ixz>
          <iyy>8.6772528526853998e-05</iyy>
          <iyz>3.2388008914376899e-21</iyz>
          <izz>5.2232830345648099e-05</izz>
        </inertia>
      </inertial>
      <collision name="rr_castor_collision">
        <pose>0 0 0 0 0 0</pose>
        <geometry>
          <sphere>
            <radius>0.025</radius>
          </sphere>
        </geometry>
        <surface>
          <friction>
            <ode>
              <mu>0.0</mu>
              <mu2>0.0</mu2>
            </ode>
          </friction>
        </surface>
      </collision>
      <visual name="rr_castor_visual">
        <pose>0 0 0 0 0 0</pose>
        <geometry>
          <mesh>
            <scale>1 1 1</scale>
            <uri>package://bugger/meshes/visual/rr_castor.STL</uri>
          </mesh>
        </geometry>
        <material>
          <diffuse>0.117647059 0.117647059 0.117647059 1</diffuse>
          <ambient>0.117647059 0.117647059 0.117647059 1</ambient>
        </material>
      </visual>
    </link>

   
    <joint name="rearlidar" type="fixed">
      <pose relative_to="base_link">0 0 0 0 0 0</pose>
      <parent>base_link</parent>
      <child>rear_lidar</child>
      <axis>
        <xyz>0 0 1</xyz>
        <limit>
          <lower>-1e+16</lower>
          <upper>1e+16</upper>
        </limit>
        <dynamics>
          <spring_reference>0</spring_reference>
          <spring_stiffness>0</spring_stiffness>
        </dynamics>
      </axis>
    </joint>
    <link name="rear_lidar">
      <pose relative_to="rearlidar">0 0 0 0 0 0</pose>
      <inertial>
        <pose>-0.19933684634509899 0.00116905028860437 0.19875374652144101 0 0 0</pose>
        <mass>0.064328080040042798</mass>
        <inertia>
          <ixx>1.20633668132683e-05</ixx>
          <ixy>1.7712824013552899e-08</ixy>
          <ixz>2.2712293543600901e-06</ixz>
          <iyy>2.8634339781214701e-05</iyy>
          <iyz>-7.5586989056283106e-09</iyz>
          <izz>3.7413990749137701e-05</izz>
        </inertia>
      </inertial>
      <collision name="rear_lidar_collision">
        <pose>0 0 0 0 0 0</pose>
        <geometry>
          <cylinder>
           <radius>0.03</radius>
           <length>0.04</length>
          </cylinder> 
        </geometry>
      </collision>
      <visual name="rear_lidar_visual">
        <pose>0 0 0 0 0 0</pose>
        <geometry>
          <mesh>
            <scale>1 1 1</scale>
            <uri>package://bugger/meshes/visual/rear_lidar.STL</uri>
          </mesh>
        </geometry>
        <material>
          <diffuse>0.990196109 1 1 1</diffuse>
          <ambient>0.990196109 1 1 1</ambient>
        </material>
      </visual>
    </link>

   
    <joint name="rightwheel" type="revolute">
      <pose relative_to="base_link">-0.0022133999999999999 -0.19925000000000001 -0.035000000000000003 0 0 0</pose>
      <parent>base_link</parent>
      <child>right_wheel</child>
      <axis>
        <xyz>0 1 0</xyz>
        <limit>
          <lower>-1e+16</lower>
          <upper>1e+16</upper>
        </limit>
        <dynamics>
          <damping>0.1</damping>
          <friction>0.1</friction>
          <spring_reference>0</spring_reference>
          <spring_stiffness>0</spring_stiffness>
        </dynamics>
      </axis>
    </joint>
    <link name="right_wheel">
      <pose relative_to="rightwheel">0 0 0 0 0 0</pose>
      <inertial>
        <pose>1.41832273394815e-05 -0.00068899426754764903 -1.8424515181303402e-05 0 0 0</pose>
        <mass>0.26616914297798</mass>
        <inertia>
          <ixx>0.00036384720729019699</ixx>
          <ixy>4.2514951574031e-08</ixy>
          <ixz>-1.8778456164125e-07</ixz>
          <iyy>0.00065937229319055796</iyy>
          <iyz>-6.0700494292680495e-08</iyz>
          <izz>0.00036341882880082502</izz>
        </inertia>
      </inertial>
      <collision name="right_wheel_collision">
        <pose>0 0 0 1.5707 0 0</pose>
        <geometry>
          <cylinder>
           <radius>0.06</radius>
           <length>0.04</length>
          </cylinder>
        </geometry>
        <surface>
          <friction>
            <ode>
              <mu>1.0</mu>
              <mu2>1.0</mu2>
              <fdir1>0 0 0</fdir1>
              <slip1>0.0</slip1>
              <slip2>0.0</slip2>
            </ode>
          </friction>
          <contact>
            <ode>
              <min_depth>0.001</min_depth>
              <kp>1e6</kp>
              <kd>100</kd>
            </ode>
          </contact>
        </surface>
      </collision>
      <visual name="right_wheel_visual">
        <pose>0 0 0 0 0 0</pose>
        <geometry>
          <mesh>
            <scale>1 1 1</scale>
            <uri>package://bugger/meshes/visual/right_wheel.STL</uri>
          </mesh>
        </geometry>
        <material>
          <diffuse>1 1 1 1</diffuse>
          <ambient>1 1 1 1</ambient>
        </material>
      </visual>
    </link>

 
    <plugin
      filename="gz-sim-diff-drive-system"
      name="gz::sim::systems::DiffDrive">
      <left_joint>leftwheel</left_joint>
      <right_joint>rightwheel</right_joint>
      <wheel_separation>0.39</wheel_separation>
      <wheel_radius>0.06</wheel_radius>
      <odom_publish_frequency>30</odom_publish_frequency>
      <topic>cmd_vel</topic>
      <odom_topic>odom</odom_topic>
      <tf_topic>tf</tf_topic>
      <frame_id>odom</frame_id>
      <child_frame_id>base_link</child_frame_id>
    </plugin>

  </model>
</sdf>